2025-06-12 20:12:20 | INFO | Starting AutoApply.AI
2025-06-12 20:12:20 | INFO | Directory structure verified
2025-06-12 20:12:20 | ERROR | Resume file not found. Please add your resume to data/resumes/resume.pdf
2025-06-12 20:13:35 | INFO | Starting AutoApply.AI
2025-06-12 20:13:35 | INFO | Directory structure verified
2025-06-12 20:13:35 | ERROR | Resume file not found. Please add your resume to data/resumes/resume.pdf
2025-06-12 20:14:31 | INFO | Starting AutoApply.AI
2025-06-12 20:14:31 | INFO | Directory structure verified
2025-06-12 20:14:31 | INFO | Configuration verified
2025-06-12 20:14:31 | INFO | Configuration loaded successfully
2025-06-12 20:14:31 | INFO | Database initialized successfully
2025-06-12 20:14:31 | ERROR | Error initializing components: Can't instantiate abstract class BaseApplicator without an implementation for abstract methods 'apply', 'is_applicable', 'login_if_needed'
2025-06-12 20:14:31 | ERROR | Application error: Can't instantiate abstract class BaseApplicator without an implementation for abstract methods 'apply', 'is_applicable', 'login_if_needed'
2025-06-12 23:27:58.493 | INFO     | __main__:main:125 - Executando fluxo completo
2025-06-12 23:27:58.496 | INFO     | __main__:run_script:45 - Running search_jobs
2025-06-12 23:28:10.650 | INFO     | __main__:run_script:45 - Running match_jobs
2025-06-12 23:28:10.908 | INFO     | __main__:run_script:45 - Running apply_jobs
2025-06-12 23:28:13.210 | ERROR    | __main__:run_script:48 - Error running apply_jobs: Command '['python', 'scripts/apply_jobs.py', '--config', 'config/config.yaml', '--resume', 'data/resumes/resume.pdf']' returned non-zero exit status 1.
2025-06-12 23:28:13.210 | ERROR    | __main__:main:140 - Falha nas candidaturas
2025-06-12 23:28:13.210 | ERROR    | __main__:main:153 - Erro: Command '['python', 'scripts/apply_jobs.py', '--config', 'config/config.yaml', '--resume', 'data/resumes/resume.pdf']' returned non-zero exit status 1.
2025-06-12 23:30:18.233 | INFO     | __main__:main:129 - Executando fluxo completo
2025-06-12 23:30:18.238 | INFO     | __main__:run_script:45 - Running search_jobs
2025-06-12 23:30:27.814 | INFO     | __main__:run_script:45 - Running match_jobs
2025-06-12 23:30:28.153 | INFO     | __main__:run_script:45 - Running apply_jobs
2025-06-12 23:30:30.750 | ERROR    | __main__:run_script:48 - Error running apply_jobs: Command '['python', 'scripts/apply_jobs.py', '--config', 'config/config.yaml', '--resume', 'data/resumes/resume.pdf', '--matches-dir', 'data/matches']' returned non-zero exit status 1.
2025-06-12 23:30:30.751 | ERROR    | __main__:main:148 - Falha nas candidaturas
2025-06-12 23:30:30.751 | ERROR    | __main__:main:161 - Erro: Command '['python', 'scripts/apply_jobs.py', '--config', 'config/config.yaml', '--resume', 'data/resumes/resume.pdf', '--matches-dir', 'data/matches']' returned non-zero exit status 1.
2025-06-12 23:31:31.699 | INFO     | __main__:main:129 - Executando fluxo completo
2025-06-12 23:31:31.700 | INFO     | __main__:run_script:45 - Running search_jobs
2025-06-12 23:31:40.714 | INFO     | __main__:run_script:45 - Running match_jobs
2025-06-12 23:31:41.064 | INFO     | __main__:run_script:45 - Running apply_jobs
2025-06-12 23:31:43.392 | ERROR    | __main__:run_script:48 - Error running apply_jobs: Command '['python', 'scripts/apply_jobs.py', '--config', 'config/config.yaml', '--resume', 'data/resumes/resume.pdf', '--matches-dir', 'data/matches']' returned non-zero exit status 1.
2025-06-12 23:31:43.392 | ERROR    | __main__:main:148 - Falha nas candidaturas
2025-06-12 23:31:43.393 | ERROR    | __main__:main:161 - Erro: Command '['python', 'scripts/apply_jobs.py', '--config', 'config/config.yaml', '--resume', 'data/resumes/resume.pdf', '--matches-dir', 'data/matches']' returned non-zero exit status 1.
2025-06-12 23:32:21.879 | INFO     | __main__:main:129 - Executando fluxo completo
2025-06-12 23:32:21.881 | INFO     | __main__:run_script:45 - Running search_jobs
2025-06-12 23:32:34.248 | INFO     | __main__:run_script:45 - Running match_jobs
2025-06-12 23:32:34.747 | INFO     | __main__:run_script:45 - Running apply_jobs
2025-06-12 23:32:37.465 | INFO     | __main__:run_script:45 - Running analyze_jobs
2025-06-12 23:32:38.730 | ERROR    | __main__:run_script:48 - Error running analyze_jobs: Command '['python', 'scripts/analyze_jobs.py']' returned non-zero exit status 1.
2025-06-12 23:32:38.731 | ERROR    | __main__:main:148 - Falha nas candidaturas
2025-06-12 23:32:38.731 | ERROR    | __main__:main:161 - Erro: Command '['python', 'scripts/analyze_jobs.py']' returned non-zero exit status 1.
2025-06-12 23:34:26.856 | INFO     | __main__:main:129 - Executando fluxo completo
2025-06-12 23:34:26.858 | INFO     | __main__:run_script:45 - Running search_jobs
2025-06-12 23:34:36.425 | INFO     | __main__:run_script:45 - Running match_jobs
2025-06-12 23:34:36.833 | INFO     | __main__:run_script:45 - Running apply_jobs
2025-06-12 23:34:39.266 | INFO     | __main__:run_script:45 - Running analyze_jobs
2025-06-12 23:54:54.950 | INFO     | __main__:main:129 - Executando fluxo completo
2025-06-12 23:54:54.952 | INFO     | __main__:run_script:45 - Running search_jobs
2025-06-12 23:55:05.973 | INFO     | __main__:run_script:45 - Running match_jobs
2025-06-12 23:55:06.407 | INFO     | __main__:run_script:45 - Running apply_jobs
2025-06-12 23:55:08.994 | INFO     | __main__:run_script:45 - Running analyze_jobs
2025-06-13 00:03:15.856 | INFO     | __main__:main:129 - Executando fluxo completo
2025-06-13 00:03:15.860 | INFO     | __main__:run_script:45 - Running search_jobs
2025-06-13 00:03:24.615 | INFO     | __main__:run_script:45 - Running match_jobs
2025-06-13 00:03:25.091 | INFO     | __main__:run_script:45 - Running apply_jobs
2025-06-13 00:03:27.427 | INFO     | __main__:run_script:45 - Running analyze_jobs
2025-06-13 00:12:09.865 | INFO     | __main__:main:139 - Executando fluxo completo
2025-06-13 00:12:09.866 | INFO     | __main__:run_script:45 - Running search_jobs
2025-06-13 00:12:10.193 | ERROR    | __main__:run_script:54 - Error running search_jobs: 2025-06-13 00:12:10.165 | ERROR    | __main__:main:188 - Error: JobSearcher.search() got an unexpected keyword argument 'keywords'
Traceback (most recent call last):
  File "/Users/felipe/autoapply_ai/scripts/search_jobs.py", line 192, in <module>
    asyncio.run(main()) 
    ^^^^^^^^^^^^^^^^^^^
  File "/Users/felipe/.pyenv/versions/3.12.5/lib/python3.12/asyncio/runners.py", line 194, in run
    return runner.run(main)
           ^^^^^^^^^^^^^^^^
  File "/Users/felipe/.pyenv/versions/3.12.5/lib/python3.12/asyncio/runners.py", line 118, in run
    return self._loop.run_until_complete(task)
           ^^^^^^^^^^^^^^^^^^^^^^^^^^^^^^^^^^^
  File "/Users/felipe/.pyenv/versions/3.12.5/lib/python3.12/asyncio/base_events.py", line 687, in run_until_complete
    return future.result()
           ^^^^^^^^^^^^^^^
  File "/Users/felipe/autoapply_ai/scripts/search_jobs.py", line 160, in main
    jobs = await searcher.search(
                 ^^^^^^^^^^^^^^^^
TypeError: JobSearcher.search() got an unexpected keyword argument 'keywords'

2025-06-13 00:12:10.193 | ERROR    | __main__:run_script:58 - Error running search_jobs: Command '['python', 'scripts/search_jobs.py']' returned non-zero exit status 1.
2025-06-13 00:12:10.193 | ERROR    | __main__:main:158 - Falha nas candidaturas
2025-06-13 00:12:10.193 | ERROR    | __main__:main:171 - Erro: Command '['python', 'scripts/search_jobs.py']' returned non-zero exit status 1.
2025-06-13 00:25:01.891 | INFO     | __main__:main:139 - Executando fluxo completo
2025-06-13 00:25:01.892 | INFO     | __main__:run_script:45 - Running search_jobs
2025-06-13 00:28:32.738 | INFO     | __main__:main:139 - Executando fluxo completo
2025-06-13 00:28:32.740 | INFO     | __main__:run_script:45 - Running search_jobs
2025-06-13 00:32:21.291 | INFO     | __main__:main:139 - Executando fluxo completo
2025-06-13 00:32:21.293 | INFO     | __main__:run_script:45 - Running search_jobs
2025-06-13 00:37:14.449 | INFO     | __main__:main:139 - Executando fluxo completo
2025-06-13 00:37:14.478 | INFO     | __main__:run_script:45 - Running search_jobs
2025-06-13 00:51:29.252 | INFO     | __main__:main:139 - Executando fluxo completo
2025-06-13 00:51:29.254 | INFO     | __main__:run_script:45 - Running search_jobs
2025-06-13 08:07:34.073 | INFO     | __main__:main:139 - Executando fluxo completo
2025-06-13 08:07:34.073 | INFO     | __main__:run_script:45 - Running search_jobs
2025-06-13 08:08:15.709 | INFO     | __main__:run_script:45 - Running match_jobs
2025-06-13 08:08:16.126 | INFO     | __main__:run_script:45 - Running apply_jobs
2025-06-13 08:08:20.336 | INFO     | __main__:run_script:45 - Running analyze_jobs
2025-06-13 08:26:59.726 | INFO     | __main__:main:139 - Executando fluxo completo
2025-06-13 08:26:59.727 | INFO     | __main__:run_script:45 - Running search_jobs
2025-06-13 08:28:41.085 | INFO     | __main__:run_script:45 - Running match_jobs
2025-06-13 08:28:41.518 | INFO     | __main__:run_script:45 - Running apply_jobs
2025-06-13 08:28:44.425 | INFO     | __main__:run_script:45 - Running analyze_jobs
2025-06-13 09:27:16.438 | INFO     | __main__:main:139 - Executando fluxo completo
2025-06-13 09:27:16.439 | INFO     | __main__:run_script:45 - Running search_jobs
2025-06-13 09:28:58.076 | INFO     | __main__:run_script:45 - Running match_jobs
2025-06-13 09:28:59.231 | INFO     | __main__:run_script:45 - Running apply_jobs
2025-06-13 09:29:02.272 | INFO     | __main__:run_script:45 - Running analyze_jobs
2025-06-13 09:35:25.614 | INFO     | __main__:main:139 - Executando fluxo completo
2025-06-13 09:35:25.616 | INFO     | __main__:run_script:45 - Running search_jobs
2025-06-13 09:37:08.044 | INFO     | __main__:run_script:45 - Running match_jobs
2025-06-13 09:37:09.261 | INFO     | __main__:run_script:45 - Running apply_jobs
2025-06-13 09:37:09.441 | ERROR    | __main__:run_script:54 - Error running apply_jobs: Traceback (most recent call last):
  File "/Users/felipe/autoapply_ai/scripts/apply_jobs.py", line 24, in <module>
    from app.automation import BaseApplicator, LinkedInApplicator, EmailApplicator
ImportError: cannot import name 'BaseApplicator' from 'app.automation' (/Users/felipe/autoapply_ai/app/automation/__init__.py)

2025-06-13 09:37:09.442 | ERROR    | __main__:run_script:58 - Error running apply_jobs: Command '['python', 'scripts/apply_jobs.py', '--config', 'config/config.yaml', '--resume', 'data/resumes/resume.pdf', '--matches-dir', 'data/matches']' returned non-zero exit status 1.
2025-06-13 09:37:09.442 | ERROR    | __main__:main:158 - Falha nas candidaturas
2025-06-13 09:37:09.442 | ERROR    | __main__:main:171 - Erro: Command '['python', 'scripts/apply_jobs.py', '--config', 'config/config.yaml', '--resume', 'data/resumes/resume.pdf', '--matches-dir', 'data/matches']' returned non-zero exit status 1.
2025-06-13 09:40:10.640 | INFO     | __main__:main:139 - Executando fluxo completo
2025-06-13 09:40:10.641 | INFO     | __main__:run_script:45 - Running search_jobs
2025-06-13 09:41:52.293 | INFO     | __main__:run_script:45 - Running match_jobs
2025-06-13 09:41:53.657 | INFO     | __main__:run_script:45 - Running apply_jobs
2025-06-13 09:41:54.291 | ERROR    | __main__:run_script:54 - Error running apply_jobs: Traceback (most recent call last):
  File "/Users/felipe/autoapply_ai/scripts/apply_jobs.py", line 24, in <module>
    from app.automation import BaseApplicator, LinkedInApplicator, EmailApplicator
  File "/Users/felipe/autoapply_ai/app/automation/__init__.py", line 5, in <module>
    from .email_applicator import EmailApplicator
  File "/Users/felipe/autoapply_ai/app/automation/email_applicator.py", line 9, in <module>
    from .email_generator import generate_email
ImportError: cannot import name 'generate_email' from 'app.automation.email_generator' (/Users/felipe/autoapply_ai/app/automation/email_generator.py)

2025-06-13 09:41:54.291 | ERROR    | __main__:run_script:58 - Error running apply_jobs: Command '['python', 'scripts/apply_jobs.py', '--config', 'config/config.yaml', '--resume', 'data/resumes/resume.pdf', '--matches-dir', 'data/matches']' returned non-zero exit status 1.
2025-06-13 09:41:54.292 | ERROR    | __main__:main:158 - Falha nas candidaturas
2025-06-13 09:41:54.292 | ERROR    | __main__:main:171 - Erro: Command '['python', 'scripts/apply_jobs.py', '--config', 'config/config.yaml', '--resume', 'data/resumes/resume.pdf', '--matches-dir', 'data/matches']' returned non-zero exit status 1.
